Workbook

Sheet Sheet1
A3: Class | B3: Interlock | C3: Description | D3: Expression | E3: Tags
A4: 2 | B4: 00015-53-1 | C4: 01SC519-15 > 1070.0 OU 01SI519-14 > 1710.0 | D4: ('//01SC519-15/PV.CV' > 1070.0) OR ('//01M519-1/BACK_PV.CV' > 1710.0) | E4: 01M519-1
B5: 1176-05-14 | C5: BACK FLOW VALVS ILOCK CLASSE 2 | D5: (('//01PC211-04/PV.CV' > 1.76) OR ('//01PI211-05/AI1/PV.CV' > 1.76 )) AND ( '//01XV211-10/DC1/PV_D.CV' != 'SJC-vlvnc-pv:FECHADA' OR '//01XV211-11/DC1/PV_D.CV' != 'SJC-vlvnc-pv:FECHADA' OR '//01XV211-12/DC1/PV_D.CV' != 'SJC-vlvnc-pv:FECHADA' OR '//01XV211-13/DC1/PV_D.CV' != 'SJC-vlvnc-pv:FECHADA' OR '//01XV211-14/DC1/PV_D.CV' != 'SJC-vlvnc-pv:FECHADA' OR '//01XV211-15/DC1/PV_D.CV' != 'SJC-vlvnc-pv:FECHADA' OR '//01XV211-16/DC1/PV_D.CV' != 'SJC-vlvnc-pv:FECHADA' OR '//01XV211-19/DC1/PV_D.CV' != 'SJC-vlvnc-pv:FECHADA' OR '//01XV211-21/DC1/PV_D.CV' != 'SJC-vlvnc-pv:FECHADA' OR '//01XV211-24/DC1/PV_D.CV' != 'SJC-vlvnc-pv:FECHADA' OR '//01XV211-31/DC1/PV_D.CV' != 'SJC-vlvnc-pv:FECHADA' OR '//01XV211-34/DC1/PV_D.CV' != 'SJC-vlvnc-pv:FECHADA' OR '//01XV211-37/DC1/PV_D.CV' != 'SJC-vlvnc-pv:FECHADA' OR '//01XV211-40/DC1/PV_D.CV' != 'SJC-vlvnc-pv:FECHADA' OR '//01XV211-43/DC1/PV_D.CV' != 'SJC-vlvnc-pv:FECHADA' OR '//01XV213-12/DC1/PV_D.CV' != 'SJC-vlvnc-pv:FECHADA' OR '//01XV381-11/DC1/PV_D.CV' != 'SJC-vlvnc-pv:FECHADA' OR '//01XV381-12/DC1/PV_D.CV' != 'SJC-vlvnc-pv:FECHADA' OR '//01XV383-10/DC1/PV_D.CV' != 'SJC-vlvnc-pv:FECHADA' OR '//01XV383-11/DC1/PV_D.CV' != 'SJC-vlvnc-pv:FECHADA' OR '//01XV383-13/DC1/PV_D.CV' != 'SJC-vlvnc-pv:FECHADA') (*OR '//01PSH211-04/PV' = TRUE) SOMENTE FISICO*) | E5: 01XV213-12
D6: (('//01PC211-04/PV.CV' > 1.76) OR ('//01PI211-05/AI1/PV.CV' > 1.76 )) AND ( '//01XV211-10/DC1/PV_D.CV' != 'SJC-vlvnc-pv:FECHADA' OR '//01XV211-11/DC1/PV_D.CV' != 'SJC-vlvnc-pv:FECHADA' OR '//01XV211-12/DC1/PV_D.CV' != 'SJC-vlvnc-pv:FECHADA' OR '//01XV211-13/DC1/PV_D.CV' != 'SJC-vlvnc-pv:FECHADA' OR '//01XV211-14/DC1/PV_D.CV' != 'SJC-vlvnc-pv:FECHADA' OR '//01XV211-15/DC1/PV_D.CV' != 'SJC-vlvnc-pv:FECHADA' OR '//01XV211-16/DC1/PV_D.CV' != 'SJC-vlvnc-pv:FECHADA' OR '//01XV211-19/DC1/PV_D.CV' != 'SJC-vlvnc-pv:FECHADA' OR '//01XV211-21/DC1/PV_D.CV' != 'SJC-vlvnc-pv:FECHADA' OR '//01XV211-24/DC1/PV_D.CV' != 'SJC-vlvnc-pv:FECHADA' OR '//01XV211-31/DC1/PV_D.CV' != 'SJC-vlvnc-pv:FECHADA' OR '//01XV211-37/DC1/PV_D.CV' != 'SJC-vlvnc-pv:FECHADA' OR '//01XV211-40/DC1/PV_D.CV' != 'SJC-vlvnc-pv:FECHADA' OR '//01XV211-43/DC1/PV_D.CV' != 'SJC-vlvnc-pv:FECHADA' OR '//01XV213-12/DC1/PV_D.CV' != 'SJC-vlvnc-pv:FECHADA' OR '//01XV381-11/DC1/PV_D.CV' != 'SJC-vlvnc-pv:FECHADA' OR '//01XV381-12/DC1/PV_D.CV' != 'SJC-vlvnc-pv:FECHADA' OR '//01XV383-10/DC1/PV_D.CV' != 'SJC-vlvnc-pv:FECHADA' OR '//01XV383-11/DC1/PV_D.CV' != 'SJC-vlvnc-pv:FECHADA' OR '//01XV383-13/DC1/PV_D.CV' != 'SJC-vlvnc-pv:FECHADA' OR '//01XV211-34/DC1/PV_D.CV' != 'SJC-vlvnc-pv:FECHADA') (*OR '//01PSH211-04/PV' = TRUE) SOMENTE FISICO*) | E6: 01XV211-10,01XV211-11,01XV211-12,01XV211-13,01XV211-14,01XV211-15,01XV211-16,01XV211-19,01XV211-21,01XV211-24,01XV211-31,01XV211-34,01XV211-37,01XV211-40,01XV211-43,01XV381-11,01XV381-12,01XV383-10,01XV383-11,01XV383-13
B7: 1176-10-8 | C7: 01PI231-04 > 25.0 OR 01PSH231-04 = HIPRS OR 01PSH231-05 = HIPRS | D7: ('//01PI231-04/PV.CV' > 25.0) (*OR ('//01PSH231-04/PV' = TRUE) OR ('//01PSH231-05/PV' = TRUE) SOMENTE FISICO*) | E7: 01XV231-07,01XV231-10
B8: 1176-22-4 | C8: 01SAH515-14 = HISPD OU 01SAH515-14.1 > 1150.0 | D8: ('//01SAH515-14/PV.CV' = TRUE) (* OR '//01SAH515-14.1/PV.CV' > 1150.0) existe somente no campo*) | E8: 01M515-2
B9: 1176-23-4 | C9: 01SAH516-14 = HISPD OU 01SAH516-14.1 > 1150.0 | D9: ('//01SAH516-14/PV.CV' = TRUE) (* OR '//01SAH516-14.1/PV.CV' > 1150.0) existe somente no campo*) | E9: 01M516-2
A10: 3 | B10: 00015-53-3 | C10: 01NAH519-17 = HIVIB | D10: ('//01NAH519-17/PV.CV' = TRUE) | E10: 01M519-1
B11: 00015-53-4 | C11: 01SAL519-15 <> LOSPD OU 01SI519-14 > 0.0 OU 01SC519-15 > 0.0 OU 01M519-7 <> DESLIGADA | D11: ('//01SAL519-15/PV.CV' != TRUE) OR ('//01M519-1/BACK_PV.CV' > 0.0) OR ('//01SC519-15/PV.CV' > 0.0) OR ('//01M519-7/PV_D' != 'SJC_MOTOR-21_PV:DESLIGADA') | E11: 01XV519-08
B12: 00015-53-5 | C12: 01XV519-08 <> TRAVADA | D12: '//01XV519-08/PV_D.CV' != 'SJC_LOCK_PV-TMP:TRAVADA' | E12: 01M519-1,01XV519-05,01XV519-18,01XV519-63
B13: 1176-05-28 | C13: 01PC211-04 > 4.2 kg/cm² OU 01PI211-05 > 4.2 kg/cm² | D13: ('//01PC211-04/PV.CV' > 4.2) OR ( '//01PI211-05/AI1/PV.CV' > 4.2 ) | E13: 01XV211-09,01XV213-10,01XV213-11,01XV231-09
B14: 1176-22-10 | C14: 01SAL515-14 <> LOSPD | D14: ('//01SAL515-14/PV.CV' != TRUE) | E14: 01XV515-09
B15: 1176-22-3 | C15: 01ZA515-09 <> FECHADA | D15: ('//01ZA515-09/PV.CV' != FALSE) | E15: 01M515-2,01XV515-03,01XV515-06,01XV515-08,01XV515-20,01XV515-31
B16: 1176-22-9 | C16: 01NAHH515-17 = HIVIB | D16: ('//01NAHH515-17/PV.CV' = TRUE) | E16: 01M515-2
B17: 1176-23-10 | C17: 01SAL516-14 <> LOSPD | D17: ('//01SAL516-14/PV.CV' != TRUE) | E17: 01XV516-09
B18: 1176-23-3 | C18: 01ZA516-09 <> FECHADA | D18: ('//01ZA516-09/PV.CV' != FALSE) | E18: 01M516-2,01XV516-03,01XV516-06,01XV516-08,01XV516-20,01XV516-31
B19: 1176-23-9 | C19: 01NAHH516-17 = HIVIB | D19: ('//01NAHH516-17/PV.CV' = TRUE) | E19: 01M516-2
B20: 1176-24-6 | C20: 01SAL640-10 = LOSPD | D20: ('//01SAL640-10/PV.CV' = TRUE) | E20: 01M640-2
B21: 1176-29-1 | C21: 01TAH930-05 = HITMP OU 01TAH930-06 = HITMP | D21: ('//01TAH930-05/PV.CV' = TRUE) OR ('//01TAH930-06/PV.CV' = TRUE) | E21: 01XV930-22
D22: ('//01TAH930-05/PV.CV' = TRUE)OR('//01TAH930-06/PV.CV' = TRUE) | E22: 01SV930-08,01XV930-21
B23: 6003-221-01 | C23: 21AI607-08 >= 8.0 OU 21AI607-12 >= 8.0) | D23: ('//21AI607-08/PV.CV' >= 8.0) OR ('//21AI607-12/PV.CV' >= 8.0); | E23: 21XV601-01
C24: 21AI607-08 => 8 OU 21AI607-12 => 8 | D24: ('//21AI607-08/PV.CV' >= 8.0) OR ('//21AI607-12/PV.CV' >= 8.0) | E24: 01M145
C25: 21AI607-08 > 8 OU 21AI607-12 > 8 | D25: ('//21AI607-08/PV.CV' > 8.0) OR ('//21AI607-12/PV.CV' > 8.0) | E25: 01M146
A26: 4 | B26: 00015-53-20 | C26: 01LI519-01 < 500.0 | D26: ('//01LI519-01/PV.CV' < 500.0) | E26: 01XV519-08
B27: 00015-53-6 | C27: 01SAL519-04 = LOSPD E 01M519-7 = LIGADA POR 30 SEG | D27: ('//01SAL519-04/PV.CV' = TRUE ) AND ('//01M519-7/PV_D' = 'SJC_MOTOR-21_PV:LIGADA') | E27: 01M519-7
B28: 00015-53-9 | C28: 01II519-03 > 8.0 POR 15 SEG | D28: ('//01II519-03/PV.CV' > 8.0) | E28: 01XV519-63
B29: 00015-54-1 | C29: 01FAL519-82 = LOFLW | D29: ('//01FAL519-82/PV.CV' = TRUE) | E29: 01M519-1
B30: 00015-54-2 | C30: 01FAL519-83 = LOFLW | D30: ('//01FAL519-83/PV.CV' = TRUE) | E30: 01M519-1
B31: 00015-54-6 | C31: 01LAL519-62 = LOLVL E 01M519-6 = LIGADA | D31: ('//01LAL519-62/PV.CV' = TRUE ) AND ('//01M519-6/PV_D' = 'SJC_MOTOR-21_PV:LIGADA') | E31: 01M519-6
B32: 00015-54-7 | C32: 01TAH519-92 > 60 ºC E 01M519-6 = LIGADA | D32: ('//01TAH519-92/PV.CV' = TRUE ) AND ('//01M519-6/PV_D' = 'SJC_MOTOR-21_PV:LIGADA') | E32: 01M519-6
B33: 00015-54-8 | C33: 01PDAH519-61 > 2 KGF E 01M519-6 = LIGADA POR 30 SEG | D33: ('//01PDAH519-61/PV.CV' = TRUE ) AND ('//01M519-6/PV_D' = 'SJC_MOTOR-21_PV:LIGADA') | E33: 01M519-6
B34: 00050-67-1 | C34: (06II945-01 < 8.5 E 06M945 = LIGADA) POR 60 SEG | D34: ('//06II945-01/PV.CV' < 8.5 AND '//06M945/PV_D' = 'SJC_MOTOR-21_PV:LIGADA') | E34: 06M945
B35: 00050-69-1 | C35: 06LAH781-02 = HILVL OU 06LI781-01 > 90.0 | D35: ('//06LAH781-02/PV' = TRUE) OR ('//06LI781-01/PV.CV' > 90.0) | E35: 06XV781-10
B36: 00050-69-10 | C36: 06M785 <> LIGADA | D36: '//06M785/PV_D' != 'SJC_MOTOR-21_PV:LIGADA' | E36: 06XV785-10,06XV785-11
B37: 00050-69-11 | C37: 06M799 <> LIGADA E 06XV796-01 <> FECHADA por 45s | D37: ( '//06M799/DC1/PV_D.CV' != 'SJC_MOTOR-21_PV:LIGADA' ) AND ( '//06XV796-01/DC1/PV_D.CV' != 'SJC-vlvnc-pv:FECHADA' ) | E37: 06XV796-01
B38: 00050-69-5 | C38: 06LI781-01 < 1.0 POR 15 SEG | D38: ('//06LI781-01/PV.CV' < 1.0) | E38: 06M785
... B40: 00050-69-7 | C40: XV785-10<>CLOSE E (DEV:06FC782-04 OU DEV:06FC782-05 OU DEV:06FC782-06 OU DEV:06FC798-01 OU DEV:06FC799-01) > 3.0% POR 180SEG | D40: '//06XV785-10/PV_D.CV' != 'SJC-vlvnc-pv:FECHADA' AND (( ABS ( '//06FC782-04/PID1/PV.CV' - '//06FC782-04/PID1/SP.CV' ) * 100 ) / ( '//06FC782-04/PID1/SP.CV' + 0.001 ) > 3.0 OR ( ABS ( '//06FC782-05/PID1/PV.CV' - '//06FC782-05/PID1/SP.CV' ) * 100 ) / ( '//06FC782-05/PID1/SP.CV' + 0.001 ) > 3.0 OR ( ABS ( '//06FC782-06/PID1/PV.CV' - '//06FC782-06/PID1/SP.CV' ) * 100 ) / ( '//06FC782-06/PID1/SP.CV' + 0.001 ) > 3.0 OR ( ( ABS ( '//06FC798-01/PID1/PV.CV' - '//06FC798-01/PID1/SP.CV' ) * 100 ) / ( '//06FC798-01/PID1/SP.CV' + 0.001 ) > 3.0 AND '//06ANTIF-SEL/SP_D.CV' = 'SJC_HABILITA_SP:HABILITA' ) OR ( ( ABS ( '//06FC799-01/PID1/PV.CV' - '//06FC799-01/PID1/SP.CV' ) * 100 ) / ( '//06FC799-01/PID1/SP.CV' + 0.001 ) > 3.0 AND '//06DYE-SEL/SP_D.CV' = 'SJC_HABILITA_SP:HABILITA' )) | E40: 06M798,06M799
D41: '//06XV785-10/PV_D.CV' != 'SJC-vlvnc-pv:FECHADA' AND (( ABS ( '//06FC782-04/PID1/PV.CV' - '//06FC782-04/PID1/SP.CV' ) * 100 ) / ( MAX(1,'//06FC782-04/PID1/SP.CV') ) > 3.0 OR ( ABS ( '//06FC782-05/PID1/PV.CV' - '//06FC782-05/PID1/SP.CV' ) * 100 ) / ( MAX(1,'//06FC782-05/PID1/SP.CV') ) > 3.0 OR ( ABS ( '//06FC782-06/PID1/PV.CV' - '//06FC782-06/PID1/SP.CV' ) * 100 ) / ( MAX(1,'//06FC782-06/PID1/SP.CV') ) > 3.0 OR ( ( ABS ( '//06FC798-01/PID1/PV.CV' - '//06FC798-01/PID1/SP.CV' ) * 100 ) / ( MAX(1,'//06FC798-01/PID1/SP.CV') ) > 3.0 AND '//06ANTIF-SEL/SP_D.CV' = 'SJC_HABILITA_SP:HABILITA' ) OR ( ( ABS ( '//06FC799-01/PID1/PV.CV' - '//06FC799-01/PID1/SP.CV' ) * 100 ) / ( MAX(1,'//06FC799-01/PID1/SP.CV') ) > 3.0 AND '//06DYE-SEL/SP_D.CV' = 'SJC_HABILITA_SP:HABILITA' )) | E41: 06XV782-10,06XV782-11,06XV785-10,06XV796-01,06XV796-02
B42: 00050-69-8 | C42: 06TI781-03 > 62 ºC | D42: ('//06TI781-03/PV.CV' > 62.0) | E42: 06M785
B43: 00050-69-9 | C43: 06XV781-04 < > TANQUE | D43: '//06XV781-04/PV_D.CV' != 'SJC_3WAY_VALVE:TANQUE'; | E43: 06XV785-10
...

Sheet tbl_Modules_data
A1: Interlock | B1: Column3 | C1: Class | D1: Expression | E1: Description | F1: Tags
A2: 01XV155-10<>ABERTAE01XV155-08<>ABERTA | B2: =VLOOKUP(tbl_Modules_data[[#This Row],[Interlock]],Sheet2!A:B,2,FALSE) -> #N/A | D2: '//01XV155-10/PV_D.CV' != 'SJC-vlvnc-pv:ABERTA' AND '//01XV155-08/PV_D.CV' != 'SJC-vlvno-pv:ABERTA' | E2: 01XV155-10 <> ABERTA E 01XV155-08 <> ABERTA | F2: 01FC155-11
A3: 01M172E01M173=DESLIGADA | B3: =VLOOKUP(tbl_Modules_data[[#This Row],[Interlock]],Sheet2!A:B,2,FALSE) -> #N/A | D3: '//01M172/DC1/PV_D.CV' = 'SJC_MOTOR-2SPD:DESLIGADA' AND '//01M173/DC1/PV_D.CV' = 'SJC_MOTOR-2SPD:DESLIGADA' | F3: 01FC170-05
A4: 01XV211-20<>ABERTA | B4: =VLOOKUP(tbl_Modules_data[[#This Row],[Interlock]],Sheet2!A:B,2,FALSE) -> #N/A | D4: ('//01XV211-20/PV_D.CV' != 'SJC-vlvnc-pv:ABERTA') | F4: 01FC211-20
A5: 1176-05-29 | B5: =VLOOKUP(tbl_Modules_data[[#This Row],[Interlock]],Sheet2!A:B,2,FALSE) -> 1176-05-29 | C5: U | D5: ('//01PC211-04/PV.CV' > 9)OR ('//01PI211-05/PV.CV' > 9) | E5: 01PC211-04 > 9 kg/cm² OU 01PI211-05 > 9 kg/cm² | F5: 01FC215-01,01XV215-06
A6: 1176-05-31 | B6: =VLOOKUP(tbl_Modules_data[[#This Row],[Interlock]],Sheet2!A:B,2,FALSE) -> 1176-05-31 | C6: U | D6: ('//01TC211-05/PV.CV' > 120.0) | E6: 01TC211-05 > 120.0 | F6: 01FC215-01
A7: 01XV215-06<>ABERTA | B7: =VLOOKUP(tbl_Modules_data[[#This Row],[Interlock]],Sheet2!A:B,2,FALSE) -> #N/A | D7: '//01XV215-06/PV_D.CV' != 'SJC-vlvnc-pv:ABERTA' | E7: 01XV215-06 <> ABERTA | F7: 01FC215-01
A8: 1176-07-4 | B8: =VLOOKUP(tbl_Modules_data[[#This Row],[Interlock]],Sheet2!A:B,2,FALSE) -> 1176-07-04 | C8: U | D8: ('//01LI220-01/PV.CV' > 40.0) OR ('//01LAH220-02/PV' = TRUE) | E8: 01LI220-01 > 40.0 OU 01LAH220-02 = HILVL | F8: 01FC229-05,01M531
A9: (01XV220-05<>ABERTAOU(01M223=DESLIGADAE01M222=DESLIGADA | B9: =VLOOKUP(tbl_Modules_data[[#This Row],[Interlock]],Sheet2!A:B,2,FALSE) -> #N/A | D9: ('//01XV220-05/PV_D.CV' != 'SJC-vlvnc-pv:ABERTA')OR ('//01M223/PV_D.CV' = 'SJC_MOTOR-21_PV:DESLIGADA' AND '//01M222/PV_D.CV' = 'SJC_MOTOR-21_PV:DESLIGADA') | E9: (01XV216-02 <> ABERTA OU (01M223 = DESLIGADA E 01M222 = DESLIGADA | F9: 01FC229-06
B10: =VLOOKUP(tbl_Modules_data[[#This Row],[Interlock]],Sheet2!A:B,2,FALSE) -> #N/A | E10: 01M233 = DESLIGADA E 01M234 = DESLIGADA | F10: 01FC238-06
A11: 01SF384-90=DESABILITADO | B11: =VLOOKUP(tbl_Modules_data[[#This Row],[Interlock]],Sheet2!A:B,2,FALSE) -> #N/A | D11: '//01SF384-90/PV.CV' = 'SJC_01SF380-90_PV:DESABILITADO' | E11: 01SF384-90 = DESABILITADO | F11: 01FC384-05
A12: 01XV384-10=ABERTA | B12: =VLOOKUP(tbl_Modules_data[[#This Row],[Interlock]],Sheet2!A:B,2,FALSE) -> #N/A | D12: '//01XV384-10/DC1/PV_D.CV' = 'SJC-vlvnc-pv:ABERTA' | E12: 01XV384-10 = ABERTA | F12: 01FC384-05
A13: 01XV460-17<>ABERTA | B13: =VLOOKUP(tbl_Modules_data[[#This Row],[Interlock]],Sheet2!A:B,2,FALSE) -> #N/A | D13: '//01XV460-17/PV_D.CV' != 'SJC-vlvnc-pv:ABERTA' | E13: 01XV460-17 <> ABERTA | F13: 01FC460-10
A14: (01M417<>LIGADAE01M418<>LIGADA)EXV415-07=FECHADA | B14: =VLOOKUP(tbl_Modules_data[[#This Row],[Interlock]],Sheet2!A:B,2,FALSE) -> #N/A | D14: ('//01M417/DC1/PV_D.CV' != 'SJC_MOTOR-21_PV:LIGADA' AND '//01M418/DC1/PV_D.CV' != 'SJC_MOTOR-21_PV:LIGADA') AND '//01XV415-07/DC1/PV_D.CV' = 'SJC-vlvnc-pv:FECHADA'; | E14: (01M417 <> LIGADA E 01M418 <> LIGADA) E XV415-07 = FECHADA | F14: 01FC460-10
A15: 01XV480-07<>ABERTAE01XV480-08<>ABERTAPOR30SEG | B15: =VLOOKUP(tbl_Modules_data[[#This Row],[Interlock]],Sheet2!A:B,2,FALSE) -> #N/A | D15: ('//01XV480-07/PV_D.CV' != 'SJC-vlvnc-pv:ABERTA') AND ('//01XV480-08/PV_D.CV' != 'SJC-vlvnc-pv:ABERTA') | E15: 01XV480-07 <> ABERTA E 01XV480-08 <> ABERTA POR 30 SEG | F15: 01FC480-06,01LC219-01A
A16: 01XV485-10<>ABERTAE01XV485-08<>ABERTA | B16: =VLOOKUP(tbl_Modules_data[[#This Row],[Interlock]],Sheet2!A:B,2,FALSE) -> #N/A | D16: ('//01XV485-10/PV_D.CV' != 'SJC-vlvnc-pv:ABERTA' AND '//01XV485-08/PV_D.CV' != 'SJC-vlvno-pv:ABERTA') | E16: 01XV485-10 <> ABERTA E 01XV485-08 <> ABERTA | F16: 01FC485-05
A17: 01XV219-05=FECHADA | B17: =VLOOKUP(tbl_Modules_data[[#This Row],[Interlock]],Sheet2!A:B,2,FALSE) -> #N/A | D17: '//01XV219-05/DC1/PV_D.CV' = 'SJC-vlvnc-pv:FECHADA' | E17: 01XV219-05 = FECHADA | F17: 01FC488-06
A18: 01XV515-20<>ABERTAE01XV515-31<>ABERTA | B18: =VLOOKUP(tbl_Modules_data[[#This Row],[Interlock]],Sheet2!A:B,2,FALSE) -> #N/A | D18: '//01XV515-20/PV_D.CV' != 'SJC-vlvnc-pv:ABERTA' AND '//01XV515-31/PV_D.CV' != 'SJC-vlvnc-pv:ABERTA' | E18: 01XV515-20 <> ABERTA E 01XV515-31 <> ABERTA | F18: 01FC515-19
A19: 01XV516-20<>ABERTAE01XV516-31<>ABERTA | B19: =VLOOKUP(tbl_Modules_data[[#This Row],[Interlock]],Sheet2!A:B,2,FALSE) -> #N/A | D19: '//01XV516-20/PV_D.CV' != 'SJC-vlvnc-pv:ABERTA' AND '//01XV516-31/PV_D.CV' != 'SJC-vlvnc-pv:ABERTA' | E19: 01XV516-20 <> ABERTA E 01XV516-31 <> ABERTA | F19: 01FC516-19
B20: =VLOOKUP(tbl_Modules_data[[#This Row],[Interlock]],Sheet2!A:B,2,FALSE) -> #N/A | D20: '//01XV519-05/PV_D.CV' != 'SJC-vlvnc-pv:ABERTA' | F20: 01FC519-02
A21: TRACKNOPATH | B21: =VLOOKUP(tbl_Modules_data[[#This Row],[Interlock]],Sheet2!A:B,2,FALSE) -> #N/A | F21: 01FC519-02
A22: 01XV520-25<>ABERTAE01XV520-07<>ABERTA | B22: =VLOOKUP(tbl_Modules_data[[#This Row],[Interlock]],Sheet2!A:B,2,FALSE) -> #N/A | D22: '//01XV520-25/PV_D.CV' != 'SJC-vlvnc-pv:ABERTA' AND '//01XV520-07/PV_D.CV' != 'SJC-vlvnc-pv:ABERTA' | E22: 01XV520-25 <> ABERTA E 01XV520-07 <> ABERTA | F22: 01FC520-05
A23: 01XV520-28<>ABERTA | B23: =VLOOKUP(tbl_Modules_data[[#This Row],[Interlock]],Sheet2!A:B,2,FALSE) -> #N/A | D23: ('//01XV520-28/PV_D.CV' != 'SJC-vlvnc-pv:ABERTA') | E23: 01XV520-28 <> ABERTA | F23: 01FC520-27
A24: 1176-30-2 | B24: =VLOOKUP(tbl_Modules_data[[#This Row],[Interlock]],Sheet2!A:B,2,FALSE) -> 1176-30-02 | C24: 4 | D24: ('//01AI255-06/PV.CV' > 2000.0) | E24: 01AI255-06 > 2000.0 | F24: 01FC785-05,01LC785-01,01M256,01M976
A25: TRACKNOPATH | B25: =VLOOKUP(tbl_Modules_data[[#This Row],[Interlock]],Sheet2!A:B,2,FALSE) -> #N/A | D25: ('//01XV640-04/PV_D.CV' != 'SJC-vlvnc-pv:ABERTA' AND '//01XV920-19/PV_D.CV' != 'SJC-vlvnc-pv:ABERTA') OR '//01XV920-20/PV_D.CV' != 'SJC-vlvnc-pv:ABERTA' | E25: 01XV640-04 <> ABERTA E 01XV920-19 <> ABERTA OU 01XV920-20 <> ABERTA | F25: 01FC920-03
A26: 1176-28-14 | B26: =VLOOKUP(tbl_Modules_data[[#This Row],[Interlock]],Sheet2!A:B,2,FALSE) -> 1176-28-14 | C26: 4 | D26: ('//01M923/PV_D' != 'SJC_MOTOR-21_PV:LIGADA') AND ('//01M924/PV_D' != 'SJC_MOTOR-21_PV:LIGADA') | E26: 01M923 <> LIGADA AND 01M924 <> LIGADA | F26: 01FC920-03,01XV920-19
A27: 1176-28-4 | B27: =VLOOKUP(tbl_Modules_data[[#This Row],[Interlock]],Sheet2!A:B,2,FALSE) -> 1176-28-04 | C27: 4 | D27: ('//01LAH920-26/PV' = TRUE) | E27: 01LAH920-26 = HILVL | F27: 01FC920-03,01FC920-29,01XV920-15,01XV920-19,01XV920-20,01XV920-24,01XV920-31
A28: TRACKNOPATH | B28: =VLOOKUP(tbl_Modules_data[[#This Row],[Interlock]],Sheet2!A:B,2,FALSE) -> #N/A | D28: '//01XV920-15/PV_D.CV' != 'SJC-vlvnc-pv:ABERTA' | E28: 01XV920-15 <> ABERTA | F28: 01FC920-29
B29: =VLOOKUP(tbl_Modules_data[[#This Row],[Interlock]],Sheet2!A:B,2,FALSE) -> #N/A | D29: (*('//01M923/PV_D' != 'SJC_MOTOR-21_PV:LIGADA') AND ('//01M924/PV_D' != 'SJC_MOTOR-21_PV:LIGADA')*) FALSE | F29: 01FC930-03
A30: TRACKNOPATH | B30: =VLOOKUP(tbl_Modules_data[[#This Row],[Interlock]],Sheet2!A:B,2,FALSE) -> #N/A | D30: '//01ALIN-FLAG/PV.CV' = 'ks_KOH_IPA_vlv_CS:INVALID' OR '//01XV930-40/PV_D.CV' != 'SJC-vlvnc-pv:ABERTA' OR '//01SV930-08/PV_D.CV' != 'SJC-vlvnc-pv:ABERTA' OR '//01XV930-21/PV_D.CV' != 'SJC-vlvnc-pv:ABERTA' OR '//01XV930-54/PV_D.CV' != 'SJC-vlv-01XV930-54-PV:BASE' | E30: ((01ALIN-FLAG = INVALID))E ((01XV930-40 <> ABERTA OU 01SV930-08 <> ABERTA)OU (01XV930-21 <> ABERTA OU 01XV930-54 <> BASE)) | F30: 01FC930-08
A31: TRACKNOPATH | B31: =VLOOKUP(tbl_Modules_data[[#This Row],[Interlock]],Sheet2!A:B,2,FALSE) -> #N/A | D31: '//01XV950-05/PV_D.CV' != 'SJC-vlvnc-pv:ABERTA' AND '//01XV960-05/PV_D.CV' != 'SJC-vlvnc-pv:ABERTA' AND '//01XV950-07/PV_D.CV' != 'SJC-vlvnc-pv:ABERTA' | E31: 01XV950-05 <> ABERTA E 01XV960-05 <> ABERTA E 01XV950-07 <> ABERTA | F31: 01FC930-27
A32: TRACKNOPATH | B32: =VLOOKUP(tbl_Modules_data[[#This Row],[Interlock]],Sheet2!A:B,2,FALSE) -> #N/A | D32: '//01XV930-24/PV_D.CV' != 'SJC-vlvnc-pv:ABERTA' | E32: 01XV930-24 <> ABERTA | F32: 01FC930-28
A33: 01M751=DESLIGADA | B33: =VLOOKUP(tbl_Modules_data[[#This Row],[Interlock]],Sheet2!A:B,2,FALSE) -> #N/A | D33: ('//01M751/PV_D' = 'SJC_MOTOR-21_PV:DESLIGADA') | E33: 01M751 = DESLIGADA | F33: 01HC640-06
A34: 01SF380-90=HABILITADO | B34: =VLOOKUP(tbl_Modules_data[[#This Row],[Interlock]],Sheet2!A:B,2,FALSE) -> #N/A | D34: '//01SF380-90/PV.CV' = 'SJC_01SF380-90_PV:HABILITADO' | E34: 01SF380-90 = HABILITADO | F34: 01LC219-01A
A35: 1176-45-1 | B35: =VLOOKUP(tbl_Modules_data[[#This Row],[Interlock]],Sheet2!A:B,2,FALSE) -> 1176-45-01 | C35: 4 | D35: ('//01LC838-01/PV.CV' > 98.0) | E35: 01LC838-01 > 98.0 | F35: 01LC838-01
A36: TRACKDEMAND | B36: =VLOOKUP(tbl_Modules_data[[#This Row],[Interlock]],Sheet2!A:B,2,FALSE) -> #N/A | D36: '//01LC920-01_TRK/ACT_TRK.CV'=TRUE | F36: 01LC920-01
A37: 01SF384-90=DESABILITADOOU01FC384-05.MODE<>CASPOR5SEG | B37: =VLOOKUP(tbl_Modules_data[[#This Row],[Interlock]],Sheet2!A:B,2,FALSE) -> #N/A | D37: '//01FC384-05_AUX/CND1_FC384-05.CV' | E37: 01SF384-90 = DESABILITADO OU 01FC384-05.MODE <> CAS POR 5 SEG | F37: 01LCH219-01,01LCH380-01,01LCL219-01,01LCL380-01
A38: 1176-34-2 | B38: =VLOOKUP(tbl_Modules_data[[#This Row],[Interlock]],Sheet2!A:B,2,FALSE) -> 1176-34-02 | C38: U | D38: ('//01II135-01/PV.CV' < 9.0) AND ('//01M135/PV_D' = 'SJC_MOTOR-21_PV:LIGADA') | E38: 01II135-01 < 9.0 e 01M135 = LIGADA POR 30 SEG | F38: 01M135
A39: 1176-34-4 | B39: =VLOOKUP(tbl_Modules_data[[#This Row],[Interlock]],Sheet2!A:B,2,FALSE) -> 1176-34-04 | C39: U | D39: ('//01XV133-08/PV_D.CV' !='SJC-vlvnc-pv:ABERTA') | E39: 01XV133-08 <> ABERTA | F39: 01M135,01M136
A40: 1176-05-33 | B40: =VLOOKUP(tbl_Modules_data[[#This Row],[Interlock]],Sheet2!A:B,2,FALSE) -> 1176-05-33 | C40: 4 | D40: '//01M837/PV_D.CV' = 'SJC_MOTOR-21_PV:DESLIGADA' AND '//01M836/PV_D.CV' = 'SJC_MOTOR-21_PV:DESLIGADA' | E40: 01M837 = DESLIGADO E 01M836 = DESLIGADO | F40: 01M135,01M136,01M158,01M159,01M213,01M233,01M234,01M256,01M341,01M526,01M528,01M531,01M976
...

Sheet Sheet2
A1: 00015-53-1
A2: 00015-53-3 | B2: 00015-53-03
A3: 00015-53-4 | B3: 00015-53-04
A4: 00015-53-5 | B4: 00015-53-05
A5: 00015-53-6 | B5: 00015-53-06
A6: 00015-53-7 | B6: 00015-53-07
A7: 00015-53-9 | B7: 00015-53-09
A8: 00015-53-11 | B8: 00015-53-11
A9: 00015-53-12 | B9: 00015-53-12
A10: 00015-53-13 | B10: 00015-53-13
A11: 00015-53-15 | B11: 00015-53-15
A12: 00015-53-16 | B12: 00015-53-16
A13: 00015-53-17 | B13: 00015-53-17
... A614: 9533D52-4 | B614: 9533-D-52-04
